Workbook

Sheet Расчет
A2: Количество сотрудников | B2: Количество сотрудников, которым будет доступна психологическая поддержка | E2: 500
A3: Тариф | B3: Оптимальный - 80% специалистов сервиса, ср. стоимость сессии 3600 р. Максимальный - 100% специалистов сервиса, ср. стоимость сессии 4400 р. | E3: Оптимальный | F3: =HLOOKUP(E3,'___'!$B$32:$D$38,7,0) -> Все форматы терапии, доступ к 80% психологов сервиса Вы готовы запустить полноценную программу поддержки при контролируемом бюджете
A4: Тип компенсации | B4: Процент - компания оплачивает долю от стоимости каждой сессии Рубли - компания оплачивает фиксированную сумму от стоимости сессии | E4: Рубли
A5: Размер компенсации | B5: Выберите сумму или процент, которую компания готова оплачивать Остаток сверх фиксированной суммы или доли доплачивает сотрудник | E5: 3500 | F5: =IF(OR(AND(E4="Процент",E5>1),AND(E4<>"Процент",E5<2)), "Выберите правильный размер компенсации", IF(AND(E4<>"Процент",E5<2499,E3='___'!$B$32), "⚠️ Низкая компенсация снижает вовлечённость. По данным Alter, при покрытии менее 2500 р. утилизация бенефита падает в среднем 2 раза", IF(AND(E4<>"Процент",E5>=2500,E3='___'!$B$32),"✅ Оптимальный вариант. Финансовый барьер для сотрудника минимален - больше сотрудников воспользуются бенефитом и получат реальную поддержку", IF(AND(E4<>"Процент",E5<1999,E3='___'!$C$32), "⚠️ Низкая компенсация снижает вовлечённость. По данным Alter, при покрытии менее 2000 р. утилизация бенефита падает в среднем в 2 раза", IF(AND(E4<>"Процент",E5>=2000,E3='___'!$C$32),"✅ Оптимальный вариант. Финансовый барьер для сотрудника минимален - больше сотрудников воспользуются бенефитом и получат реальную поддержку", IF(E4<>"Процент", "", IF(E5=0.3, "⚠️ Низкая компенсация. При покрытии до 50% большинство сотрудников воспринимают бенефит как номинальный и не пользуются им.", IF(E5=0.5, "Сотрудник оплачивает половину стоимости сессии самостоятельно. Финансовая нагрузка может стать причиной, по которой часть сотрудников не воспользуется бенефитом или быстро перестанет ходить.", "✅ Оптимальный вариант. Финансовый барьер для сотрудника минимален - больше сотрудников воспользуются бенефитом и получат реальную поддержку.") ) ) ) )))) -> ✅ Оптимальный вариант. Финансовый барьер для сотрудника минимален - больше сотрудников воспользуются бенефитом и получат реальную поддержку
A6: Доступ сотрудника | B6: Прямой - не нужно делать дополнительные шаги для активации скидки Непрямой - для получения скидки нужно обратиться к HR или заполнить форму | E6: Прямой доступ | F6: =IF(E6='___'!C83,"⚠️ Дополнительный барьер снижает активацию. По данным Alter, при непрямом доступе бенефитом воспользуется в 3 раза меньше сотрудников. Рекомендуем прямой доступ - так больше сотрудников воспользуются бенефитом, и программа принесёт реальный результат.","")
A10: Прогноз бюджета для _______________
A11: Лимит сессий в месяц Максимальное количество сессий от компании в месяц на одного сотрудника | B11: Прогноз вовлечённости, % | C11: Прогноз активных сотрудников | D11: Ср. число сессий на сотрудника в год | E11: Итого сессий за год | F11: Средняя стоимость сессии для компании, ₽ | G11: Ср. платеж (в месяц) | H11: ИТОГО прогноз бюджета (год), ₽
A12: 1 сессия в месяц Может восприниматься, как номинальный бенефит. Это влияет на вовлечённость: часть сотрудников не начнет пользоваться | B12: ='___'!B74 -> 0.03 | C12: ='___'!C74 -> 15 | D12: ='___'!D74 -> 5 | E12: ='___'!E74 -> 75 | F12: ='___'!F74 -> 3500 | G12: =H12/12 -> 21875 | H12: ='___'!G74 -> 262500
A13: 2 или 3 сессии в месяц Комфортный ритм для пользователей. Ср. кол-во сессий на пользователя в мес. составляет 3 | B13: ='___'!B75 -> 0.05 | C13: ='___'!C75 -> 25 | D13: ='___'!D75 -> 7 | E13: ='___'!E75 -> 175 | F13: ='___'!F75 -> 3500 | G13: =H13/12 -> 51041.667 | H13: ='___'!G75 -> 612500
A14: 4 и более сессии в месяц Дают сотруднику возможность полноценно работать над запросом, а программа принесет максимальную пользу | B14: ='___'!B76 -> 0.13 | C14: ='___'!C76 -> 65 | D14: ='___'!D76 -> 12 | E14: ='___'!E76 -> 780 | F14: ='___'!F76 -> 3500 | G14: =H14/12 -> 227500 | H14: ='___'!G76 -> 2730000

Sheet Издержки на текучку
A1: Калькулятор расчета издержек на замену 1 сотрудника
A3: Заполните ячейки, выделенные зелёным цветом
A5: Компонент | B5: Примерные расходы | C5: Комментарий
A6: Выходное пособие, отпускные | B6: 1 оклад | C6: Обычно оплате подлежат неотгуленные дни и компенсации по ТК РФ.
A7: Поиск и найм (услуги, время HR) | B7: 0,5-1 оклада | C7: Работа рекрутеров или внешних агентств. Платные вакансии, размещения на job-сайтах, время команды на отсмотр и интервьюирование.
A8: Адаптация и обучение | B8: 0,5-1 оклада | C8: Время наставников и HR на адаптацию нового сотрудника. Затраты на обучение (внешние/внутренние курсы, тренинги).
A9: Потери продуктивности (3 мес. -30%) | B9: 0,5 оклада | C9: Новый сотрудник первые 3–6 месяцев работает с меньшей эффективностью. Коллегам требуется время на помощь новому члену команды.
A10: Ошибки и простои | B10: 0,2-0,5 оклада | C10: В период замещения команда недоукомплектована, возрастает нагрузка, случаются сбои в бизнес-процессах. Ошибки новичков (особенно на сложных, экспертных позициях).
A11: Итого | B11: 2,7-4 оклада
A13: Средний оклад | B13: 100000
A14: Средние расходы на замену сотрудника | B14: =B13*3.35 -> 335000 | C14: Столько компания тратит на замену 1 сотрудника
A17: Калькулятор расчета издержек на текучку
A19: Количество сотрудников в компании | B19: 100
A20: Текучесть кадров | B20: 0.1
A21: В среднем в год уходит сотрудников | B21: =B19*B20 -> 10
A22: Издержки на текучку | B22: =B21*B14 -> 3350000 | C22: Столько компания теряет в год на текучести кадров

Sheet ___
A1: Скидки
D2: нефикс | F2: фикс
A3: amount | B3: type
A4: 1500 | B4: Рубли | D4: {=IF('___'!B4:B20 = 'Расчет'!E4, '___'!A4:A20, "")} -> 1500 | F4: 1000
A5: =A4+500 -> 2000 | B5: Рубли | D5: 2000 | F5: 1500
A6: =A5+500 -> 2500 | B6: Рубли | D6: 2500 | F6: 2000
A7: =A6+500 -> 3000 | B7: Рубли | D7: 3000 | F7: 2800
A8: =A7+500 -> 3500 | B8: Рубли | D8: 3500
A9: =A8+500 -> 4000 | B9: Рубли | D9: 4000
A10: =A9+500 -> 4500 | B10: Рубли | D10: 4500
A11: =A10+500 -> 5000 | B11: Рубли | D11: 5000
A12: 0.3 | B12: Процент
A13: 0.5 | B13: Процент
A14: 0.7 | B14: Процент
A15: 1 | B15: Процент
A18: Описание
A21: Текущий "нейминг" (как говорим между собой) | B21: Нефикс (без ограничений) | C21: Нефикс (с ограничением на выдачу до 5к) | D21: Фикс 2800 | E21: Фикс 2400
A22: Размер базы (реальный) | B22: 100% психологов | C22: 80% психологов | D22: 30% психологов | E22: 13% психологов
A23: Индивидуальная терапия | B23: да | C23: да | D23: да | E23: да
A24: Семейная терапия | B24: да | C24: да | D24: нет | E24: нет
A25: Детская / подростковая терапия | B25: да | C25: да | D25: нет | E25: нет
A26: Офлайн | B26: да | C26: да | D26: нет | E26: нет
A27: Коучинг | B27: да | C27: нет | D27: нет | E27: нет
A28: Стоимость сессии | B28: = установленной у психолога | C28: = установленной у психолога | D28: единая / зафиксирована для компании | E28: единая / зафиксирована для компании
A29: Средний чек | B29: 4400 | C29: 3600 | D29: 2800 | E29: 2400
A32: Нейминг (предварительно) для сайта / презы / калькулятора | B32: Максимальный | C32: Оптимальный | D32: Фиксированный
A33: Доступность | B33: 100% психологов | C33: ~80% психологов | D33: Не более 50% психологов
A34: Форматы | B34: Все форматы терапии + коучинг | C34: Все форматы терапии | D34: Индивидуальная терапия онлайн
A35: Стоимость сессии | B35: Различная - установлена психологом | C35: Различная - установлена психологом | D35: Фиксированная - согласуем под ваш бюджет
A36: Для кого | B36: Благополучие команды - ваш приоритет - вы готовы закрыть буквально любой запрос ваших сотрудников. | C36: Вы готовы запустить полноценную программу поддержки при контролируемом бюджете. | D36: Вы готовы протестировать формат поддержки и начать с базового набора возможностей.
A37: Средняя стоимость | B37: ~ 4 400 р. | C37: ~ 3 600 р. | D37: ~ 2 600 р.
A38: Алерт | B38: Все форматы терапии + коучинг, доступ к 100% психологов сервиса Благополучие команды - ваш приоритет - вы готовы закрыть буквально любой запрос ваших сотрудников | C38: Все форматы терапии, доступ к 80% психологов сервиса Вы готовы запустить полноценную программу поддержки при контролируемом бюджете | D38: Индивидуальная терапия онлайн, доступны не более 50% психологов сервиса
B39: 4400 | C39: 3600 | D39: 2800
A44: non-FIX formulas
A46: Количество сотрудников | B46: Количество сотрудников, которым будет доступна психологическая поддержка | E46: ='фикс '!E2 -> #REF! | N46: =IF(E46<51,1,if(E46<251,2,3)) -> #REF!
A47: Тариф | B47: Фиксированный тариф - стоимость любой сессии 2800 рублей, до 50% специалистов сервиса, только индивидуальная терапия онлайн | E47: ='фикс '!E3 -> #REF! | N47: =if(N48<50%,4,if(N48<70%,3,if(N48<100%,2,1))) -> #REF!
A48: Размер компенсации | B48: Выберите сумму, которую компания готова оплачивать Остаток сверх фиксированной суммы доплачивает сотрудник | E48: ='фикс '!E4 -> #REF! | F48: =IF(E48<1250,"⚠️ Низкая компенсация снижает вовлечённость. По данным Alter, при покрытии менее 50% стоимости сессии утилизация бенефита падает в среднем в 2 раза","") -> #REF! | N48: =ROUNDUP(E48/'___'!$D$39,1) -> #REF!
A49: Доступ сотрудника | B49: Прямой - не нужно делать дополнительные шаги для активации скидки Непрямой - для получения скидки нужно обратиться к HR или заполнить форму | E49: ='фикс '!E5 -> #REF! | F49: =IF(E49='___'!C83,"⚠️ Дополнительный барьер снижает активацию. По данным Alter, при непрямом доступе бенефитом воспользуется в 3 раза меньше сотрудников. Рекомендуем прямой доступ - так больше сотрудников воспользуются бенефитом, и программа принесёт реальный результат.","") -> #REF! | N49: =IF(E49='___'!C82,1,4) -> #REF!
A53: Прогноз бюджета
A54: Лимит сессий в месяц Максимальное количество сессий от компании в месяц на одного сотрудника | B54: Прогноз вовлечённости, % | C54: Прогноз активных сотрудников | D54: Ср. число сессий на сотрудника в год | E54: Итого сессий за год | F54: Стоимость сессии для компании, ₽ | G54: ИТОГО годовой бюджет, ₽
...
